Workbook

Sheet RECAP
P1: ALT COINS | AU1: PRIX | AV1: lien | AW1: Crypto Prices
B2: PAIR | C2: $BTC* | D2: $ETH | E2: $TON | F2: $SOL* | G2: $TAO* | H2: ALT | I2: USDC | P2: $RON | Q2: $LINK | R2: $DOGE | S2: $SHIB | T2: $CAKE | U2: $JUP | V2: $AAVE | W2: $CKB | X2: $PENDLE | Y2: $BOME | Z2: $PEPE | AA2: $WIF | AB2: $RAY | AT2: $BTC | AU2: 67500 | AV2: https://cryptoprices.cc/BTC/ | AW2: =IFERROR(__xludf.DUMMYFUNCTION("IMPORTDATA(AV2)"),67315.0) -> 67315
A3: PF at | B3: 46071 | C3: =C4*C6 -> 24971.317 | D3: =D4*D6 -> 3517.6425 | E3: =E4*E6 -> 0.0020019876 | F3: =F4*F6 -> 0 | G3: =G4*G6 -> 0 | H3: =SUM(P3:AA3) -> -0.0024058335 | I3: =I4*I6 -> 10332.394 | P3: =P4*P6 -> 0 | Q3: =Q4*Q6 -> 0 | R3: =R4*R6 -> -0.0041718684 | S3: =S4*S6 -> -1.2644183e-07 | T3: =T4*T6 -> 0 | U3: =U4*U6 -> 0 | V3: =V4*V6 -> 0 | W3: =W4*W6 -> 0 | ... AB3: =AB4*AB6 -> 0 | AT3: $ETH | AU3: 1950 | AV3: https://cryptoprices.cc/ETH/ | AW3: =IFERROR(__xludf.DUMMYFUNCTION("IMPORTDATA(AV3)"),"1972.35") -> 1972.35
A4: QTY at | B4: =ARBITRAGES!E268 -> 46066 | C4: =VLOOKUP($B$4,'QUANTITE DETENUES'!1:999,2,FALSE) -> 0.36994544 | D4: =VLOOKUP($B$4,'QUANTITE DETENUES'!1:999,3,FALSE) -> 1.8039192 | E4: =VLOOKUP($B$4,'QUANTITE DETENUES'!1:999,4,FALSE) -> 0.0013902692 | F4: =VLOOKUP($B$4,'QUANTITE DETENUES'!1:999,5,FALSE) -> 0 | G4: =VLOOKUP($B$4,'QUANTITE DETENUES'!1:999,6,FALSE) -> 0 | H4: - | I4: =VLOOKUP(B4,PRIX!1:998,20) -> 10332.394 | P4: =VLOOKUP($B$4,'QUANTITE DETENUES'!1:999,7,FALSE) -> 0 | Q4: =VLOOKUP($B$4,'QUANTITE DETENUES'!1:999,8,FALSE) -> 0 | R4: =VLOOKUP($B$4,'QUANTITE DETENUES'!1:999,9,FALSE) -> -0.041760444 | S4: =VLOOKUP($B$4,'QUANTITE DETENUES'!1:999,10,FALSE) -> -0.01945259 | T4: =VLOOKUP($B$4,'QUANTITE DETENUES'!1:999,11,FALSE) -> 0 | U4: =VLOOKUP($B$4,'QUANTITE DETENUES'!1:999,12,FALSE) -> 0 | V4: =VLOOKUP($B$4,'QUANTITE DETENUES'!1:999,13,FALSE) -> 0 | W4: =VLOOKUP($B$4,'QUANTITE DETENUES'!1:999,14,FALSE) -> 0 | X4: =VLOOKUP($B$4,'QUANTITE DETENUES'!1:999,15,FALSE) -> 0.0014612915 | Y4: =VLOOKUP($B$4,'QUANTITE DETENUES'!1:999,16,FALSE) -> 0.028919892 | Z4: =VLOOKUP($B$4,'QUANTITE DETENUES'!1:999,17,FALSE) -> 0.039999998 | AA4: =VLOOKUP($B$4,'QUANTITE DETENUES'!1:999,18,FALSE) -> 0 | AB4: =VLOOKUP($B$4,'QUANTITE DETENUES'!1:999,19,FALSE) -> 0 | AT4: $TON | AU4: 1.44 | AV4: https://cryptoprices.cc/TON/ | AW4: =IFERROR(__xludf.DUMMYFUNCTION("IMPORTDATA(AV4)"),"1.44") -> 1.44
B5: Pondération (%) | C5: =C3/$K$11 -> 0.64323665 | D5: =D3/$K$11 -> 0.090611023 | E5: =E3/$K$11 -> 5.1569239e-08 | F5: =F3/$K$11 -> 0 | G5: =G3/$K$11 -> 0 | H5: =H3/$K$11 -> -6.1971914e-08 | I5: =I3/$K$11 -> 0.26615234 | P5: =P3/$K$11 -> 0 | Q5: =Q3/$K$11 -> 0 | R5: =R3/$K$11 -> -1.0746324e-07 | S5: =S3/$K$11 -> 0 | T5: =T3/$K$11 -> 0 | U5: =U3/$K$11 -> 0 | V5: =V3/$K$11 -> 0 | W5: =W3/$K$11 -> 0 | ... AB5: =AB3/$K$11 -> 0 | AT5: $SOL | AU5: 83 | AV5: https://cryptoprices.cc/SOL/ | AW5: =IFERROR(__xludf.DUMMYFUNCTION("IMPORTDATA(AV5)"),"82.69") -> 82.69
B6: PRIX ACTUELS | C6: =AU2 -> 67500 | D6: =AU3 -> 1950 | E6: =AU4 -> 1.44 | F6: =AU5 -> 83 | G6: =AU6 -> 190 | H6: - | I6: 1 | P6: =AU7 -> 0.096 | Q6: =AU8 -> 8.7 | R6: =AU9 -> 0.0999 | S6: =AU10 -> 6.5e-06 | T6: =AU11 -> 1.3 | U6: =AU12 -> 0.157 | V6: =AU13 -> 125 | W6: =AU14 -> 0.00165 | X6: =AU15 -> 1.2 | Y6: =AU16 -> 0.00043 | Z6: =AU17 -> 4.4e-06 | AA6: =AU18 -> 0.23 | AB6: =AU19 -> 0.6 | AT6: $TAO | AU6: 190 | AV6: https://cryptoprices.cc/TAO/ | AW6: =IFERROR(__xludf.DUMMYFUNCTION("IMPORTDATA(AV6)"),"189.87") -> 189.87
B7: Prix d'entrée | C7: 59283 | D7: 2405 | E7: 6.28 | F7: 141 | G7: 317 | H7: - | I7: - | P7: 1.61 | Q7: 10.95 | R7: 0.10172 | S7: 1.4e-05 | T7: 1.6 | U7: 0.9355 | V7: 172.58 | W7: 0.0111 | X7: 4.29 | Y7: 0.009774 | Z7: 1.78e-05 | AA7: 3.35 | AB7: 6.35 | AT7: $RON | AU7: 0.096 | AV7: https://cryptoprices.cc/RON | AW7: =IFERROR(__xludf.DUMMYFUNCTION("IMPORTDATA(AV7)"),"0.098075") -> 0.098075
B8: PERF (par rapport au PMA) | C8: =(C6-C7)/C7 -> 0.13860635 | D8: =(D6-D7)/D7 -> -0.18918919 | E8: =(E6-E7)/E7 -> -0.77070064 | F8: =(F6-F7)/F7 -> -0.41134752 | G8: =(G6-G7)/G7 -> -0.40063091 | H8: =(P8*P5+Q8*Q5+R8*R5+S8*S5+T8*T5+U8*U5+V8*V5+W5*W8+X5*X8+Y5*Y8+Z5*Z8+AA5*AA8+AB5*AB8)/H5 -> 0.49893536 | P8: =(P6-P7)/P7 -> -0.94037267 | Q8: =(Q6-Q7)/Q7 -> -0.20547945 | R8: =(R6-R7)/R7 -> -0.017892253 | S8: =(S6-S7)/S7 -> -0.53571429 | T8: =(T6-T7)/T7 -> -0.1875 | U8: =(U6-U7)/U7 -> -0.83217531 | V8: =(V6-V7)/V7 -> -0.27569823 | W8: =(W6-W7)/W7 -> -0.85135135 | ... AB8: =(AB6-AB7)/AB7 -> -0.90551181 | AT8: $LINK | AU8: 8.7 | AV8: https://cryptoprices.cc/LINK/ | AW8: =IFERROR(__xludf.DUMMYFUNCTION("IMPORTDATA(AV8)"),"8.71") -> 8.71
I9: AUJOURD'HUI | AT9: $DOGE | AU9: 0.0999 | AV9: https://cryptoprices.cc/DOGE/ | AW9: =IFERROR(__xludf.DUMMYFUNCTION("IMPORTDATA(AV9)"),"0.099931") -> 0.099931
I10: TOTAL INVESTI | K10: PORTFOLLIO | M10: ROI % | N10: ROI $ | AT10: $SHIB | AU10: 6.5e-06 | AV10: https://cryptoprices.cc/SHIB/ | AW10: =IFERROR(__xludf.DUMMYFUNCTION("IMPORTDATA(AV10)"),"6.42e-06") -> 6.42e-06
I11: =VLOOKUP($B$4,BILAN!1:1000,14) -> 37467.522 | K11: =SUM(C3:I3) -> 38821.353 | M11: =(K11-I11)/I11 -> 0.036133457 | N11: =K11-I11 -> 1353.8311 | AT11: $CAKE | AU11: 1.3 | AV11: https://cryptoprices.cc/CAKE/ | AW11: =IFERROR(__xludf.DUMMYFUNCTION("IMPORTDATA(AV11)"),"1.29") -> 1.29
AT12: $JUP | AU12: 0.157 | AV12: https://cryptoprices.cc/JUP/ | AW12: =IFERROR(__xludf.DUMMYFUNCTION("IMPORTDATA(AV12)"),"0.160764") -> 0.160764
AT13: $AAVE | AU13: 125 | AV13: https://cryptoprices.cc/AAVE/ | AW13: =IFERROR(__xludf.DUMMYFUNCTION("IMPORTDATA(AV13)"),"125.79") -> 125.79
AT14: $CKB | AU14: 0.00165 | AV14: https://cryptoprices.cc/CKB/ | AW14: =IFERROR(__xludf.DUMMYFUNCTION("IMPORTDATA(AV14)"),"0.00164314") -> 0.00164314
AT15: $PENDLE | AU15: 1.2 | AV15: https://cryptoprices.cc/PENDLE/ | AW15: =IFERROR(__xludf.DUMMYFUNCTION("IMPORTDATA(AV15)"),"1.22") -> 1.22
AT16: $BOME | AU16: 0.00043 | AV16: https://cryptoprices.cc/BOME/ | AW16: =IFERROR(__xludf.DUMMYFUNCTION("IMPORTDATA(AV16)"),"0.00042636") -> 0.00042636
AT17: $PEPE | AU17: 4.4e-06 | AV17: https://cryptoprices.cc/PEPE/ | AW17: =IFERROR(__xludf.DUMMYFUNCTION("IMPORTDATA(AV17)"),"4.32e-06") -> 4.32e-06
AT18: $WIF | AU18: 0.23 | AV18: https://cryptoprices.cc/WIF/ | AW18: =IFERROR(__xludf.DUMMYFUNCTION("IMPORTDATA(AV18)"),"0.227432") -> 0.227432
J19: Global perf from 11/08 | N19: =IF(M19="","", IF(J19="Invest",#REF!-K19,#REF!+K19)) | AT19: $RAY | AU19: 0.6 | AV19: https://cryptoprices.cc/RAY/ | AW19: =IFERROR(__xludf.DUMMYFUNCTION("IMPORTDATA(AV19)"),"0.661748") -> 0.661748
J20: $BTC | K20: 63000 | L20: =C6 -> 67500 | M20: =(L20-K20)/K20 -> 0.071428571
J21: $ETH | K21: 2650 | L21: =D6 -> 1950 | M21: =(L21-K21)/K21 -> -0.26415094
J22: $TON | K22: 6.666 | L22: =E6 -> 1.44 | M22: =(L22-K22)/K22 -> -0.7839784
J23: $SOL | K23: 155 | L23: =F6 -> 83 | M23: =(L23-K23)/K23 -> -0.46451613
J24: $TAO | K24: 295 | L24: =G6 -> 190 | M24: =(L24-K24)/K24 -> -0.3559322
J25: $RON | K25: 1.55 | L25: =P6 -> 0.096 | M25: =(L25-K25)/K25 -> -0.93806452
J26: $LINK | K26: 10.2 | L26: =Q6 -> 8.7 | M26: =(L26-K26)/K26 -> -0.14705882
J27: $DOGE | K27: 0.1025 | L27: =R6 -> 0.0999 | M27: =(L27-K27)/K27 -> -0.025365854
J28: Sp500 | K28: 5350 | L28: 7000 | M28: =(L28-K28)/K28 -> 0.30841122
J29: Nasdaq 100 | K29: 19000 | L29: 25200 | M29: =(L29-K29)/K29 -> 0.32631579
J30: $$$ | K30: 45515 | L30: Aujourd'hui | M30: Perf
A107: PAIR | B107: $BTC | C107: $ETH | D107: $TON | E107: $SOL | F107: $TAO | G107: $RON | H107: $LINK | I107: $DOGE | J107: $SHIB | K107: $CAKE | L107: $JUP | M107: $AAVE | N107: $CKB | O107: $PENDLE | P107: USDC
A108: =B3 -> 46071 | B108: =C3 -> 24971.317 | C108: =D3 -> 3517.6425 | D108: =E3 -> 0.0020019876 | E108: =F3 -> 0 | F108: =G3 -> 0 | G108: =P3 -> 0 | H108: =Q3 -> 0 | I108: =R3 -> -0.0041718684 | J108: =S3 -> -1.2644183e-07 | K108: =T3 -> 0 | L108: =U3 -> 0 | M108: =V3 -> 0 | N108: =W3 -> 0 | O108: =X3 -> 0.0017535498 | P108: =I3 -> 10332.394

Sheet ARBITRAGES
A1: ARBITRAGES | P1: .
E2: DATE | F2: +/- | G2: $ INJECTED | H2: ACTIF | I2: PRIX ($) | J2: MONTANT ($) | K2: QUANTITE | L2: Frais | M2: Liquidités | N2: Surperf/Sousperf
E3: 45515 | F3: Invest | G3: $21 550,45 | H3: USDC | I3: $ 1,00 | J3: $21 550,44 | K3: 21550 | L3: $1,00 | M3: 21550 | N3: 1
E4: 45515 | F4: Invest | G4: 0 | H4: BTC | I4: $ 58 000,00 | J4: 7500 | K4: 0.12931 | L4: 0 | M4: =IF(E4="","",IF(G4=0,IF(F4="Invest",M3-J4-L4,M3+J4),M3)) -> 14050 | N4: 1
E5: 45516 | F5: Invest | G5: 0 | H5: ETH | I5: $ 2 600,00 | J5: 3000 | K5: 1.1538 | L5: 0 | M5: =IF(E5="","",IF(G5=0,IF(F5="Invest",M4-J5-L5,M4+J5),M4)) -> 11050 | N5: 1
E6: 45517 | F6: Invest | G6: 0 | H6: SOL | I6: $ 145,00 | J6: 1150 | K6: 7.931 | L6: 0 | M6: =IF(E6="","",IF(G6=0,IF(F6="Invest",M5-J6-L6,M5+J6),M5)) -> 9900 | N6: 1
E7: 45518 | F7: Invest | G7: 0 | H7: TAO | I7: 279.2 | J7: 840 | K7: 3 | L7: 0 | M7: =IF(E7="","",IF(G7=0,IF(F7="Invest",M6-J7-L7,M6+J7),M6)) -> 9060 | N7: 1
E8: 45518 | F8: Invest | G8: 0 | H8: RON | I8: 1.54 | J8: 310 | K8: 200 | L8: 0 | M8: =IF(E8="","",IF(G8=0,IF(F8="Invest",M7-J8-L8,M7+J8),M7)) -> 8750 | N8: 1
E9: 45519 | F9: Invest | G9: 0 | H9: TON | I9: 6.48 | J9: 2750 | K9: =IF(J9=0,"",IF(H9="USDC",J9,(J9/I9))) -> 424.38272 | L9: 0 | M9: =IF(E9="","",IF(G9=0,IF(F9="Invest",M8-J9-L9,M8+J9),M8)) -> 6000 | N9: 1
E10: 45522 | F10: Invest | G10: 0 | H10: BTC | I10: 57500 | J10: 1500 | K10: =IF(J10=0,"",IF(H10="USDC",J10,(J10/I10))) -> 0.026086957 | L10: 0 | M10: =IF(E10="","",IF(G10=0,IF(F10="Invest",M9-J10-L10,M9+J10),M9)) -> 4500 | N10: 1
E11: 45527 | F11: Retrait | G11: 0 | H11: TAO | I11: 345 | J11: 345 | K11: =IF(J11=0,"",IF(H11="USDC",J11,(J11/I11))) -> 1 | L11: 0 | M11: =IF(E11="","",IF(G11=0,IF(F11="Invest",M10-J11-L11,M10+J11),M10)) -> 4845 | N11: 1
E12: 45527 | F12: Retrait | G12: 0 | H12: SOL | I12: 155 | J12: 1500 | K12: =IF(J12=0,"",IF(H12="USDC",J12,(J12/I12))) -> 9.6774194 | L12: 0 | M12: =IF(E12="","",IF(G12=0,IF(F12="Invest",M11-J12-L12,M11+J12),M11)) -> 6345 | N12: 1
E13: 45528 | F13: Retrait | G13: 0 | H13: SOL | I13: 157.5 | J13: 1833 | K13: =IF(J13=0,"",IF(H13="USDC",J13,(J13/I13))) -> 11.638095 | L13: 0 | M13: =IF(E13="","",IF(G13=0,IF(F13="Invest",M12-J13-L13,M12+J13),M12)) -> 8178 | N13: 1
E14: 45529 | F14: Invest | G14: 0 | H14: TON | I14: 6 | J14: 500 | K14: =IF(J14=0,"",IF(H14="USDC",J14,(J14/I14))) -> 83.333333 | L14: 0 | M14: =IF(E14="","",IF(G14=0,IF(F14="Invest",M13-J14-L14,M13+J14),M13)) -> 7678 | N14: 0
E15: 45530 | F15: Invest | G15: 0 | H15: BTC | I15: 62100 | J15: 2200 | K15: =IF(J15=0,"",IF(H15="USDC",J15,(J15/I15))) -> 0.035426731 | L15: 0 | M15: =IF(E15="","",IF(G15=0,IF(F15="Invest",M14-J15-L15,M14+J15),M14)) -> 5478 | N15: 1
E16: 45531 | F16: Invest | G16: 0 | H16: RON | I16: 1.65 | J16: 825 | K16: =IF(J16=0,"",IF(H16="USDC",J16,(J16/I16))) -> 500 | L16: 0 | M16: =IF(E16="","",IF(G16=0,IF(F16="Invest",M15-J16-L16,M15+J16),M15)) -> 4653 | N16: 1
E17: 45531 | F17: Invest | G17: 0 | H17: TAO | I17: 330 | J17: 1155 | K17: =IF(J17=0,"",IF(H17="USDC",J17,(J17/I17))) -> 3.5 | L17: 0 | M17: =IF(E17="","",IF(G17=0,IF(F17="Invest",M16-J17-L17,M16+J17),M16)) -> 3498 | N17: 1
E18: 45531 | F18: Invest | G18: 0 | H18: DOGE | I18: 0.102 | J18: 280.5 | K18: =IF(J18=0,"",IF(H18="USDC",J18,(J18/I18))) -> 2750 | L18: 0 | M18: =IF(E18="","",IF(G18=0,IF(F18="Invest",M17-J18-L18,M17+J18),M17)) -> 3217.5 | N18: 1
E19: 45531 | F19: Invest | G19: 0 | H19: LINK | I19: 11 | J19: 1100 | K19: =IF(J19=0,"",IF(H19="USDC",J19,(J19/I19))) -> 100 | L19: 0 | M19: =IF(E19="","",IF(G19=0,IF(F19="Invest",M18-J19-L19,M18+J19),M18)) -> 2117.5 | N19: 1
E20: 45532 | F20: Invest | G20: 0 | H20: BTC | I20: 58800 | J20: 1300 | K20: =IF(J20=0,"",IF(H20="USDC",J20,(J20/I20))) -> 0.022108844 | L20: 0 | M20: =IF(E20="","",IF(G20=0,IF(F20="Invest",M19-J20-L20,M19+J20),M19)) -> 817.5 | N20: 1
... E40: 45609 | F40: Invest | G40: 0 | H40: JUP | I40: 1.1 | J40: 500.5 | K40: =IF(J40=0,"",IF(H40="USDC",J40,(J40/I40))) -> 455 | L40: 0 | M40: =IF(E40="","",IF(G40=0,IF(F40="Invest",M39-J40-L40,M39+J40),M39)) -> 2895.4656 | N40: 0
E41: 45610 | F41: Invest | G41: 0 | H41: BTC | I41: 88000 | J41: 1320 | K41: =IF(J41=0,"",IF(H41="USDC",J41,(J41/I41))) -> 0.015 | L41: 0 | M41: =IF(E41="","",IF(G41=0,IF(F41="Invest",M40-J41-L41+10,M40+J41),M40)) -> 1585.4656 | N41: 1
E42: 45615 | F42: Retrait | G42: 0 | H42: SHIB | I42: 2.6e-05 | J42: 377 | K42: =IF(J42=0,"",IF(H42="USDC",J42,(J42/I42))) -> 14500000 | L42: 0 | M42: =IF(E42="","",IF(G42=0,IF(F42="Invest",M41-J42-L42,M41+J42),M41)) -> 1962.4656 | N42: 0
E43: 45618 | F43: Invest | G43: 0 | H43: PENDLE | I43: 4.8885 | J43: 440 | K43: =IF(J43=0,"",IF(H43="USDC",J43,(J43/I43))) -> 90.00716 | L43: 0 | M43: =IF(E43="","",IF(G43=0,IF(F43="Invest",M42-J43-L43,M42+J43),M42)) -> 1522.4656 | N43: 0
E44: 45619 | F44: Invest | G44: 0 | H44: BOME | I44: 0.009774 | J44: 175.932 | K44: =IF(J44=0,"",IF(H44="USDC",J44,(J44/I44))) -> 18000 | L44: 0 | M44: =IF(E44="","",IF(G44=0,IF(F44="Invest",M43-J44-L44,M43+J44),M43)) -> 1346.5336 | N44: 0
E45: 45622 | F45: Invest | G45: 0 | H45: WIF | I45: 3.35 | J45: 197.65 | K45: =IF(J45=0,"",IF(H45="USDC",J45,(J45/I45))) -> 59 | L45: 0 | M45: =IF(E45="","",IF(G45=0,IF(F45="Invest",M44-J45-L45,M44+J45),M44)) -> 1148.8836 | N45: 0
E46: 45630 | F46: Retrait | G46: 0 | H46: CAKE | I46: 4.33 | J46: 108.31 | K46: =IF(J46=0,"",IF(H46="USDC",J46,(J46/I46))) -> 25.013857 | L46: 0.08 | M46: =IF(E46="","",IF(G46=0,IF(F46="Invest",M45-J46-L46,M45+J46),M45)) -> 1257.1936 | N46: 1
E47: 45636 | F47: Invest | G47: 0 | H47: SOL | I47: 210 | J47: 420 | K47: =IF(J47=0,"",IF(H47="USDC",J47,(J47/I47))) -> 2 | L47: 0 | M47: =IF(E47="","",IF(G47=0,IF(F47="Invest",M46-J47-L47,M46+J47),M46)) -> 837.19364 | N47: 1
E48: 45644 | F48: Invest | G48: 0 | H48: PEPE | I48: 2e-05 | J48: 279 | K48: =IF(J48=0,"",IF(H48="USDC",J48,(J48/I48))) -> 13950000 | L48: 0 | M48: =IF(E48="","",IF(G48=0,IF(F48="Invest",M47-J48-L48,M47+J48),M47)) -> 558.19364 | N48: 1
E49: 45646 | F49: Invest | G49: 0 | H49: PEPE | I49: 1.5e-05 | J49: 150 | K49: =IF(J49=0,"",IF(H49="USDC",J49,(J49/I49))) -> 10000000 | L49: 0 | M49: =IF(E49="","",IF(G49=0,IF(F49="Invest",M48-J49-L49,M48+J49),M48)) -> 408.19364 | N49: 1
E50: 45658 | F50: Invest | G50: 0 | H50: PENDLE | I50: 4.85 | J50: 201.275 | K50: =IF(J50=0,"",IF(H50="USDC",J50,(J50/I50))) -> 41.5 | L50: 0 | M50: =IF(E50="","",IF(G50=0,IF(F50="Invest",M49-J50-L50,M49+J50),M49)) -> 206.91864 | N50: 0
E51: 45666 | F51: Invest | G51: 0 | H51: TAO | I51: 430 | J51: 193.5 | K51: =IF(J51=0,"",IF(H51="USDC",J51,(J51/I51))) -> 0.45 | L51: 0 | M51: =IF(E51="","",IF(G51=0,IF(F51="Invest",M50-J51-L51,M50+J51),M50)) -> 13.418639 | N51: 1
E52: 45676 | F52: Retrait | G52: 0 | H52: SOL | I52: 280 | J52: 280 | K52: =IF(J52=0,"",IF(H52="USDC",J52,(J52/I52))) -> 1 | L52: 0 | M52: =IF(E52="","",IF(G52=0,IF(F52="Invest",M51-J52-L52,M51+J52),M51)) -> 293.41864 | N52: 1
E53: 45677 | F53: Invest | G53: 0 | H53: RAY | I53: 6.35 | J53: 279.4 | K53: =IF(J53=0,"",IF(H53="USDC",J53,(J53/I53))) -> 44 | L53: 0 | M53: =IF(E53="","",IF(G53=0,IF(F53="Invest",M52-J53-L53,M52+J53),M52)) -> 14.018639 | N53: 1
... E72: 45779 | F72: Retrait | G72: 0 | H72: BTC | I72: 97000 | J72: 970 | K72: =IF(J72=0,"",IF(H72="USDC",J72,(J72/I72))) -> 0.01 | L72: 0 | M72: =IF(E72="","",IF(G72=0,IF(F72="Invest",M71-J72-L72,M71+J72),M71)) -> 1571.1596 | N72: 1
E73: 45779 | F73: Retrait | G73: 0 | H73: BTC | I73: 98000 | J73: 980 | K73: 0.01 | L73: 0 | M73: =IF(E73="","",IF(G73=0,IF(F73="Invest",M72-J73-L73,M72+J73),M72)) -> 2551.1596 | N73: 1
E74: 45785 | F74: Retrait | G74: 0 | H74: BTC | I74: 102000 | J74: 1020 | K74: =IF(J74=0,"",IF(H74="USDC",J74,(J74/I74))) -> 0.01 | L74: 0 | M74: =IF(E74="","",IF(G74=0,IF(F74="Invest",M73-J74-L74,M73+J74),M73)) -> 3571.1596 | N74: 1
E75: 45785 | F75: Retrait | G75: 0 | H75: BTC | I75: 102500 | J75: 1266.1487 | K75: =IF(J75=0,"",IF(H75="USDC",J75,(J75/I75))) -> 0.01235267 | L75: 0 | M75: =IF(E75="","",IF(G75=0,IF(F75="Invest",M74-J75-L75,M74+J75),M74)) -> 4837.3083 | N75: 0
E76: 45054 | F76: Retrait | G76: 0 | H76: RON | I76: 0.59 | J76: 222.55174 | K76: =IF(J76=0,"",IF(H76="USDC",J76,(J76/I76))) -> 377.20633 | L76: 0 | M76: =IF(E76="","",IF(G76=0,IF(F76="Invest",M75-J76-L76,M75+J76),M75)) -> 5059.86 | N76: 0
E77: 45786 | F77: Retrait | G77: 0 | H77: TAO | I77: 425 | J77: 425 | K77: =IF(J77=0,"",IF(H77="USDC",J77,(J77/I77))) -> 1 | L77: 0 | M77: =IF(E77="","",IF(G77=0,IF(F77="Invest",M76-J77-L77,M76+J77),M76)) -> 5484.86 | N77: 1
...

Sheet HISTORIQUE RAPIDE
A2: DATE | B2: INITIAL ENTRY | C2: ACTUAL PORTFOLLIO | D2: ROI % | E2: PV
A3: =ARBITRAGES!E3 -> 45515 | B3: =BILAN!N3 -> 37467.522 | C3: =BILAN!O3 -> 37684.606 | D3: =(C3-B3)/B3 -> 0.0057939408 | E3: =C3-B3 -> 217.0846
A4: =IF(ARBITRAGES!E4="","",ARBITRAGES!E4) -> 45515 | B4: =BILAN!N4 -> 37467.522 | C4: =BILAN!O4 -> 39187.939 | D4: =(C4-B4)/B4 -> 0.04591757 | E4: =C4-B4 -> 1720.4176
A5: =IF(ARBITRAGES!E5="","",ARBITRAGES!E5) -> 45516 | B5: =BILAN!N5 -> 37467.522 | C5: =BILAN!O5 -> 38425.058 | D5: =(C5-B5)/B5 -> 0.025556434 | E5: =C5-B5 -> 957.53625
A6: =IF(ARBITRAGES!E6="","",ARBITRAGES!E6) -> 45517 | B6: =BILAN!N6 -> 37467.522 | C6: =BILAN!O6 -> 38797.452 | D6: =(C6-B6)/B6 -> 0.035495565 | E6: =C6-B6 -> 1329.9308
A7: =IF(ARBITRAGES!E7="","",ARBITRAGES!E7) -> 45518 | B7: =BILAN!N7 -> 37467.522 | C7: =BILAN!O7 -> 38816.265 | D7: =(C7-B7)/B7 -> 0.035997663 | E7: =C7-B7 -> 1348.7432
A8: =IF(ARBITRAGES!E8="","",ARBITRAGES!E8) -> 45518 | B8: =BILAN!N8 -> 37467.522 | C8: =BILAN!O8 -> 38836.265 | D8: =(C8-B8)/B8 -> 0.036531459 | E8: =C8-B8 -> 1368.7432
A9: =IF(ARBITRAGES!E9="","",ARBITRAGES!E9) -> 45519 | B9: =BILAN!N9 -> 37467.522 | C9: =BILAN!O9 -> 37999.572 | D9: =(C9-B9)/B9 -> 0.014200307 | E9: =C9-B9 -> 532.05032
A10: =IF(ARBITRAGES!E10="","",ARBITRAGES!E10) -> 45522 | B10: =BILAN!N10 -> 37467.522 | C10: =BILAN!O10 -> 38621.63 | D10: =(C10-B10)/B10 -> 0.030802901 | E10: =C10-B10 -> 1154.1083
A11: =IF(ARBITRAGES!E11="","",ARBITRAGES!E11) -> 45527 | B11: =BILAN!N11 -> 37467.522 | C11: =BILAN!O11 -> 40071.087 | D11: =(C11-B11)/B11 -> 0.069488585 | E11: =C11-B11 -> 2603.5651
A12: =IF(ARBITRAGES!E12="","",ARBITRAGES!E12) -> 45527 | B12: =BILAN!N12 -> 37467.522 | C12: =BILAN!O12 -> 40130.796 | D12: =(C12-B12)/B12 -> 0.071082223 | E12: =C12-B12 -> 2663.2747
A13: =IF(ARBITRAGES!E13="","",ARBITRAGES!E13) -> 45528 | B13: =BILAN!N13 -> 37467.522 | C13: =BILAN!O13 -> 40893.775 | D13: =(C13-B13)/B13 -> 0.091445958 | E13: =C13-B13 -> 3426.2534
A14: =IF(ARBITRAGES!E14="","",ARBITRAGES!E14) -> 45529 | B14: =BILAN!N14 -> 37467.522 | C14: =BILAN!O14 -> 40117.46 | D14: =(C14-B14)/B14 -> 0.070726265 | E14: =C14-B14 -> 2649.9379
A15: =IF(ARBITRAGES!E15="","",ARBITRAGES!E15) -> 45530 | B15: =BILAN!N15 -> 37467.522 | C15: =BILAN!O15 -> 38900.624 | D15: =(C15-B15)/B15 -> 0.038249185 | E15: =C15-B15 -> 1433.1022
... A34: =IF(ARBITRAGES!E34="","",ARBITRAGES!E34) -> 45602 | B34: =BILAN!N34 -> 37467.522 | C34: =BILAN!O34 -> 45167.981 | D34: =(C34-B34)/B34 -> 0.20552359 | E34: =C34-B34 -> 7700.4597
A35: 45603 | B35: =IF(A35="","",B34) -> 37467.522 | C35: 46153.166 | D35: =(C35-B35)/B35 -> 0.23181797 | E35: =C35-B35 -> 8685.6447
A36: 45605 | B36: =IF(A36="","",B35) -> 37467.522 | C36: 49222.315 | D36: =IF(C36="","",(C36-B36)/B36) -> 0.31373287 | E36: =IF(C36="","",C36-B36) -> 11754.793
A37: 45607 | B37: =IF(A37="","",B36) -> 37467.522 | C37: 51641.25 | D37: =IF(C37="","",(C37-B37)/B37) -> 0.37829373 | E37: =IF(C37="","",C37-B37) -> 14173.728
A38: 45608 | B38: =IF(C38="","",B37) -> 37467.522 | C38: 54284.52 | D38: =IF(C38="","",(C38-B38)/B38) -> 0.44884203 | E38: =IF(C38="","",C38-B38) -> 16816.998
A39: 45609 | B39: =IF(C39="","",B38) -> 37467.522 | C39: 51403.192 | D39: =IF(C39="","",(C39-B39)/B39) -> 0.37194002 | E39: =IF(C39="","",C39-B39) -> 13935.671
A40: 45610 | B40: =IF(C40="","",B39) -> 37467.522 | C40: 51527.826 | D40: =IF(C40="","",(C40-B40)/B40) -> 0.37526647 | E40: =IF(C40="","",C40-B40) -> 14060.304
A41: 45613 | B41: =IF(C41="","",B40) -> 37467.522 | C41: 53158.117 | D41: =IF(C41="","",(C41-B41)/B41) -> 0.41877856 | E41: =IF(C41="","",C41-B41) -> 15690.595
A42: 45615 | B42: =IF(C42="","",B41) -> 37467.522 | C42: 53867.707 | D42: =IF(C42="","",(C42-B42)/B42) -> 0.43771737 | E42: =IF(C42="","",C42-B42) -> 16400.185
A43: 45617 | B43: =IF(C43="","",B42) -> 37467.522 | C43: 56248.56 | D43: =IF(C43="","",(C43-B43)/B43) -> 0.50126183 | E43: =IF(C43="","",C43-B43) -> 18781.038
A44: 45619 | B44: =IF(C44="","",B43) -> 37467.522 | C44: 58682.42 | D44: =IF(C44="","",(C44-B44)/B44) -> 0.56622102 | E44: =IF(C44="","",C44-B44) -> 21214.898
A45: 45621 | B45: =IF(C45="","",B44) -> 37467.522 | C45: 58525.26 | D45: =IF(C45="","",(C45-B45)/B45) -> 0.56202645 | E45: =IF(C45="","",C45-B45) -> 21057.738
A46: 45622 | B46: =IF(C46="","",B45) -> 37467.522 | C46: 54937.25 | D46: =IF(C46="","",(C46-B46)/B46) -> 0.46626325 | E46: =IF(C46="","",C46-B46) -> 17469.728
A47: 45624 | B47: =IF(C47="","",B46) -> 37467.522 | C47: 58243.56 | D47: =IF(C47="","",(C47-B47)/B47) -> 0.55450794 | E47: =IF(C47="","",C47-B47) -> 20776.038
A48: 45625 | B48: =IF(C48="","",B47) -> 37467.522 | C48: 60084.09 | D48: =IF(C48="","",(C48-B48)/B48) -> 0.60363129 | E48: =IF(C48="","",C48-B48) -> 22616.568
A49: 45628 | B49: =IF(C49="","",B48) -> 37467.522 | C49: 58531.42 | D49: =IF(C49="","",(C49-B49)/B49) -> 0.56219086 | E49: =IF(C49="","",C49-B49) -> 21063.898
... A69: 45680 | B69: =IF(C69="","",B68) -> 37467.522 | C69: 57532.15 | D69: =IF(C69="","",(C69-B69)/B69) -> 0.53552056 | E69: =IF(C69="","",C69-B69) -> 20064.628
A70: 45687 | B70: =IF(C70="","",B68) -> 37467.522 | C70: 56523.14 | D70: =IF(C70="","",(C70-B70)/B70) -> 0.50859031 | E70: =IF(C70="","",C70-B70) -> 19055.618
A71: 45692 | B71: =IF(C71="","",B69) -> 37467.522 | C71: 51213.21 | D71: =IF(C71="","",(C71-B71)/B71) -> 0.36686943 | E71: =IF(C71="","",C71-B71) -> 13745.688
A72: 45695 | B72: =IF(C72="","",B71) -> 37467.522 | C72: 49452.15 | D72: =IF(C72="","",(C72-B72)/B72) -> 0.31986712 | E72: =IF(C72="","",C72-B72) -> 11984.628
A73: 45698 | B73: =IF(C73="","",B72) -> 37467.522 | C73: 52341.87 | D73: =IF(C73="","",(C73-B73)/B73) -> 0.39699312 | E73: =IF(C73="","",C73-B73) -> 14874.348
A74: 45700 | B74: =IF(C74="","",B73) -> 37467.522 | C74: 50632.64 | D74: =IF(C74="","",(C74-B74)/B74) -> 0.35137414 | E74: =IF(C74="","",C74-B74) -> 13165.118
A75: 45702 | B75: =IF(C75="","",B74) -> 37467.522 | C75: 49241.18 | D75: =IF(C75="","",(C75-B75)/B75) -> 0.31423638 | E75: =IF(C75="","",C75-B75) -> 11773.658
A76: 45705 | B76: =IF(C76="","",B75) -> 37467.522 | C76: 51986.2 | D76: =IF(C76="","",(C76-B76)/B76) -> 0.38750037 | E76: =IF(C76="","",C76-B76) -> 14518.678
A77: 45707 | B77: =IF(C77="","",B76) -> 37467.522 | C77: 48862.47 | D77: =IF(C77="","",(C77-B77)/B77) -> 0.30412869 | E77: =IF(C77="","",C77-B77) -> 11394.948
A78: 45711 | B78: =IF(C78="","",B77) -> 37467.522 | C78: 50136.4 | D78: =IF(C78="","",(C78-B78)/B78) -> 0.33812961 | E78: =IF(C78="","",C78-B78) -> 12668.878
...

Sheet PV (%)
Q2: $BTC | R2: $ETH | S2: $TON | T2: $SOL | U2: $TAO | V2: $RON | W2: $LINK | X2: $DOGE | Y2: total
B3: Date | C3: Investissement | D3: $BTC | E3: Portefeuille full BTC | F3: Portefeuille sans arbitrage | G3: Portefeuille avec arbitrage | H3: Plus value | I3: ROI GLOBAL | Q3: =Q4*$Y$3 -> 16860.385 | R3: =R4*$Y$3 -> 7493.5043 | S3: =S4*$Y$3 -> 3746.7522 | T3: =T4*$Y$3 -> 3746.7522 | U3: =U4*$Y$3 -> 1873.3761 | V3: =V4*$Y$3 -> 1873.3761 | W3: =W4*$Y$3 -> 1498.7009 | X3: =X4*$Y$3 -> 374.67522 | Y3: =C4 -> 37467.522
B4: =IF(ARBITRAGES!E4=0,"",ARBITRAGES!E4) -> 45515 | C4: =BILAN!N4 -> 37467.522 | D4: =IF(F4="","",PRIX!B3) -> 63000 | E4: =IF(F4="","",($G$4/$D$4)*D4) -> 37467.522 | F4: =IF(B4="","",G4) -> 37467.522 | G4: =IF(B4="","",C4) -> 37467.522 | H4: =IF(B4="","",(G4-F4)/F4) -> 0 | I4: =IF(H4="","",(G4-C4)/C4) -> 0 | P4: Quantité prévue (%) | Q4: 0.45 | R4: 0.2 | S4: 0.1 | T4: 0.1 | U4: 0.05 | V4: 0.05 | W4: 0.04 | X4: 0.01 | Y4: =SUM(Q4:X4) -> 1
B5: =IF(ARBITRAGES!E5=0,"",ARBITRAGES!E5) -> 45516 | C5: =IF(F5="","",C4) -> 37467.522 | D5: =IF(F5="","",PRIX!B4) -> 63000 | E5: =IF(F5="","",($G$4/$D$4)*D5) -> 37467.522 | F5: =IF(B5="","",PRIX!B5*$Q$6+$R$6*PRIX!C5+PRIX!D5*$S$6+$T$6*PRIX!E5+PRIX!F5*$U$6+PRIX!G5*$V$6+$W$6*PRIX!H5+PRIX!I5*$X$6) -> 36849.451 | G5: =IF(B5="","",'Historique détail'!U4) -> 39187.939 | H5: =IF(B5="","",(G5-F5)/F5) -> 0.063460607 | I5: =IF(H5="","",(G5-C5)/C5) -> 0.04591757 | P5: PMA | Q5: 60800 | R5: 2650 | S5: 7.61 | T5: 155 | U5: 300 | V5: 1.6 | W5: 11.5 | X5: 0.105 | Y5: -
B6: =IF(ARBITRAGES!E6=0,"",ARBITRAGES!E6) -> 45517 | C6: =IF(F6="","",C5) -> 37467.522 | D6: =IF(F6="","",PRIX!B5) -> 59800 | E6: =IF(F6="","",($G$4/$D$4)*D6) -> 35564.409 | F6: =IF(B6="","",PRIX!B6*$Q$6+$R$6*PRIX!C6+PRIX!D6*$S$6+$T$6*PRIX!E6+PRIX!F6*$U$6+PRIX!G6*$V$6+$W$6*PRIX!H6+PRIX!I6*$X$6) -> 37173.715 | G6: =IF(B6="","",'Historique détail'!U5) -> 38425.058 | H6: =IF(B6="","",(G6-F6)/F6) -> 0.03366203 | I6: =IF(H6="","",(G6-C6)/C6) -> 0.025556434 | P6: Quantité prévue | Q6: =Q3/Q5 -> 0.27730896 | R6: =R3/R5 -> 2.8277375 | S6: =S3/S5 -> 492.34588 | T6: =T3/T5 -> 24.172595 | U6: =U3/U5 -> 6.2445869 | V6: =V3/V5 -> 1170.8601 | W6: =W3/W5 -> 130.32181 | X6: =X3/X5 -> 3568.3354 | Y6: -
B7: =IF(ARBITRAGES!E7=0,"",ARBITRAGES!E7) -> 45518 | C7: =IF(F7="","",C6) -> 37467.522 | D7: =IF(F7="","",PRIX!B6) -> 61000 | E7: =IF(F7="","",($G$4/$D$4)*D7) -> 36278.077 | F7: =IF(B7="","",PRIX!B7*$Q$6+$R$6*PRIX!C7+PRIX!D7*$S$6+$T$6*PRIX!E7+PRIX!F7*$U$6+PRIX!G7*$V$6+$W$6*PRIX!H7+PRIX!I7*$X$6) -> 37126.881 | G7: =IF(B7="","",'Historique détail'!U6) -> 38797.452 | H7: =IF(B7="","",(G7-F7)/F7) -> 0.044996286 | I7: =IF(H7="","",(G7-C7)/C7) -> 0.035495565 | P7: Prix actuel | Q7: =RECAP!AU2 -> 67500 | R7: =RECAP!AU3 -> 1950 | S7: =RECAP!AU4 -> 1.44 | T7: =RECAP!AU5 -> 83 | U7: =RECAP!AU6 -> 190 | V7: =RECAP!AU7 -> 0.096 | W7: =RECAP!AU8 -> 8.7 | X7: =RECAP!AU9 -> 0.0999 | Y7: =Q6*Q7+R6*R7+S6*S7+T6*T7+U6*U7+V6*V7+W6*W7+X6*X7 -> 29736.897
B8: =IF(ARBITRAGES!E9=0,"",ARBITRAGES!E9) -> 45519 | C8: =IF(F8="","",C7) -> 37467.522 | D8: =IF(F8="","",PRIX!B7) -> 61000 | E8: =IF(F8="","",($G$4/$D$4)*D8) -> 36278.077 | F8: =IF(B8="","",PRIX!B9*$Q$6+$R$6*PRIX!C9+PRIX!D9*$S$6+$T$6*PRIX!E9+PRIX!F9*$U$6+PRIX!G9*$V$6+$W$6*PRIX!H9+PRIX!I9*$X$6) -> 35694.108 | G8: =IF(B8="","",'Historique détail'!U8) -> 38836.265 | H8: =IF(B8="","",(G8-F8)/F8) -> 0.088030118 | I8: =IF(H8="","",(G8-C8)/C8) -> 0.036531459 | K8: Moyenne de performance
B9: =IF(ARBITRAGES!E10=0,"",ARBITRAGES!E10) -> 45522 | C9: =IF(F9="","",C8) -> 37467.522 | D9: =IF(F9="","",PRIX!B8) -> 61000 | E9: =IF(F9="","",($G$4/$D$4)*D9) -> 36278.077 | F9: =IF(B9="","",PRIX!B10*$Q$6+$R$6*PRIX!C10+PRIX!D10*$S$6+$T$6*PRIX!E10+PRIX!F10*$U$6+PRIX!G10*$V$6+$W$6*PRIX!H10+PRIX!I10*$X$6) -> 36536.792 | G9: =IF(B9="","",'Historique détail'!U9) -> 37999.572 | H9: =IF(B9="","",(G9-F9)/F9) -> 0.04003582 | I9: =IF(H9="","",(G9-C9)/C9) -> 0.014200307 | K9: 10 dernier jours | L9: =AVERAGE(H195:H205) -> 0.19011918
B10: =IF(ARBITRAGES!E11=0,"",ARBITRAGES!E11) -> 45527 | C10: =IF(F10="","",C9) -> 37467.522 | D10: =IF(F10="","",PRIX!B9) -> 58000 | E10: =IF(F10="","",($G$4/$D$4)*D10) -> 34493.909 | F10: =IF(B10="","",PRIX!B11*$Q$6+$R$6*PRIX!C11+PRIX!D11*$S$6+$T$6*PRIX!E11+PRIX!F11*$U$6+PRIX!G11*$V$6+$W$6*PRIX!H11+PRIX!I11*$X$6) -> 38338.251 | G10: =IF(B10="","",'Historique détail'!U10) -> 38621.63 | H10: =IF(B10="","",(G10-F10)/F10) -> 0.0073915584 | I10: =IF(H10="","",(G10-C10)/C10) -> 0.030802901 | K10: le mois en cours | L10: =AVERAGE(H163:H205) -> 0.17038752
B11: =IF(ARBITRAGES!E12=0,"",ARBITRAGES!E12) -> 45527 | C11: =IF(F11="","",C10) -> 37467.522 | D11: =IF(F11="","",PRIX!B10) -> 60100 | E11: =IF(F11="","",($G$4/$D$4)*D11) -> 35742.826 | F11: =IF(B11="","",PRIX!B12*$Q$6+$R$6*PRIX!C12+PRIX!D12*$S$6+$T$6*PRIX!E12+PRIX!F12*$U$6+PRIX!G12*$V$6+$W$6*PRIX!H12+PRIX!I12*$X$6) -> 38338.251 | G11: =IF(B11="","",'Historique détail'!U11) -> 40071.087 | H11: =IF(B11="","",(G11-F11)/F11) -> 0.045198623 | I11: =IF(H11="","",(G11-C11)/C11) -> 0.069488585 | K11: 6 dernier mois | L11: =AVERAGE(H59:H205) -> 0.097221009
B12: =IF(ARBITRAGES!E13=0,"",ARBITRAGES!E13) -> 45528 | C12: =IF(F12="","",C11) -> 37467.522 | D12: =IF(F12="","",PRIX!B11) -> 63400 | E12: =IF(F12="","",($F$4/$D$4)*D12) -> 37705.411 | F12: =IF(B12="","",PRIX!B13*$Q$6+$R$6*PRIX!C13+PRIX!D13*$S$6+$T$6*PRIX!E13+PRIX!F13*$U$6+PRIX!G13*$V$6+$W$6*PRIX!H13+PRIX!I13*$X$6) -> 39159.97 | G12: =IF(B12="","",'Historique détail'!U12) -> 40130.796 | H12: =IF(B12="","",(G12-F12)/F12) -> 0.024791302 | I12: =IF(H12="","",(G12-C12)/C12) -> 0.071082223 | K12: l'année en cours | L12: =AVERAGE(H:H) -> 0.11438787
B13: =IF(ARBITRAGES!E14=0,"",ARBITRAGES!E14) -> 45529 | C13: =IF(F13="","",C12) -> 37467.522 | D13: =IF(F13="","",PRIX!B12) -> 63400 | E13: =IF(F13="","",($F$4/$D$4)*D13) -> 37705.411 | F13: =IF(B13="","",PRIX!B14*$Q$6+$R$6*PRIX!C14+PRIX!D14*$S$6+$T$6*PRIX!E14+PRIX!F14*$U$6+PRIX!G14*$V$6+$W$6*PRIX!H14+PRIX!I14*$X$6) -> 38233.711 | G13: =IF(B13="","",'Historique détail'!U13) -> 40893.775 | H13: =IF(B13="","",(G13-F13)/F13) -> 0.069573791 | I13: =IF(H13="","",(G13-C13)/C13) -> 0.091445958
B14: =IF(ARBITRAGES!E15=0,"",ARBITRAGES!E15) -> 45530 | C14: =IF(F14="","",C13) -> 37467.522 | D14: =IF(F14="","",PRIX!B13) -> 64400 | E14: =IF(F14="","",($G$4/$D$4)*D14) -> 38300.133 | F14: =IF(B14="","",PRIX!B15*$Q$6+$R$6*PRIX!C15+PRIX!D15*$S$6+$T$6*PRIX!E15+PRIX!F15*$U$6+PRIX!G15*$V$6+$W$6*PRIX!H15+PRIX!I15*$X$6) -> 36872.135 | G14: =IF(B14="","",'Historique détail'!U14) -> 40117.46 | H14: =IF(B14="","",(G14-F14)/F14) -> 0.088015649 | I14: =IF(H14="","",(G14-C14)/C14) -> 0.070726265
B15: =IF(ARBITRAGES!E16=0,"",ARBITRAGES!E16) -> 45531 | C15: =IF(F15="","",C14) -> 37467.522 | D15: =IF(F15="","",PRIX!B14) -> 64000 | E15: =IF(F15="","",($G$4/$D$4)*D15) -> 38062.244 | F15: =IF(B15="","",PRIX!B16*$Q$6+$R$6*PRIX!C16+PRIX!D16*$S$6+$T$6*PRIX!E16+PRIX!F16*$U$6+PRIX!G16*$V$6+$W$6*PRIX!H16+PRIX!I16*$X$6) -> 36872.135 | G15: =IF(B15="","",'Historique détail'!U15) -> 38900.624 | H15: =IF(B15="","",(G15-F15)/F15) -> 0.055014149 | I15: =IF(H15="","",(G15-C15)/C15) -> 0.038249185
B16: =IF(ARBITRAGES!E20=0,"",ARBITRAGES!E20) -> 45532 | C16: =IF(F16="","",C15) -> 37467.522 | D16: =IF(F16="","",PRIX!B15) -> 62000 | E16: =IF(F16="","",($G$4/$D$4)*D16) -> 36872.799 | F16: =IF(B16="","",PRIX!B20*$Q$6+$R$6*PRIX!C20+PRIX!D20*$S$6+$T$6*PRIX!E20+PRIX!F20*$U$6+PRIX!G20*$V$6+$W$6*PRIX!H20+PRIX!I20*$X$6) -> 35451.629 | G16: =IF(B16="","",'Historique détail'!U19) -> 38937.508 | H16: =IF(B16="","",(G16-F16)/F16) -> 0.098327755 | I16: =IF(H16="","",(G16-C16)/C16) -> 0.039233626
B17: =IF(ARBITRAGES!E21=0,"",ARBITRAGES!E21) -> 45545 | C17: =IF(F17="","",C16) -> 37467.522 | D17: =IF(F17="","",PRIX!B16) -> 62000 | E17: =IF(F17="","",($F$4/$D$4)*D17) -> 36872.799 | F17: =IF(B17="","",PRIX!B21*$Q$6+$R$6*PRIX!C21+PRIX!D21*$S$6+$T$6*PRIX!E21+PRIX!F21*$U$6+PRIX!G21*$V$6+$W$6*PRIX!H21+PRIX!I21*$X$6) -> 33732.789 | G17: =IF(B17="","",'Historique détail'!U20) -> 37571.824 | H17: =IF(B17="","",(G17-F17)/F17) -> 0.1138072 | I17: =IF(H17="","",(G17-C17)/C17) -> 0.0027838007
B18: =IF(ARBITRAGES!E22=0,"",ARBITRAGES!E22) -> 45551 | C18: =IF(F18="","",C17) -> 37467.522 | D18: =IF(F18="","",PRIX!B17) -> 62000 | E18: =IF(F18="","",($F$4/$D$4)*D18) -> 36872.799 | F18: =IF(B18="","",PRIX!B22*$Q$6+$R$6*PRIX!C22+PRIX!D22*$S$6+$T$6*PRIX!E22+PRIX!F22*$U$6+PRIX!G22*$V$6+$W$6*PRIX!H22+PRIX!I22*$X$6) -> 34523.808 | G18: =IF(B18="","",'Historique détail'!U21) -> 35856.037 | H18: =IF(B18="","",(G18-F18)/F18) -> 0.038588717 | I18: =IF(H18="","",(G18-C18)/C18) -> -0.043010175
B19: =IF(ARBITRAGES!E23=0,"",ARBITRAGES!E23) -> 45552 | C19: =IF(F19="","",C18) -> 37467.522 | D19: =IF(F19="","",PRIX!B18) -> 62000 | E19: =IF(F19="","",($F$4/$D$4)*D19) -> 36872.799 | F19: =IF(B19="","",PRIX!B23*$Q$6+$R$6*PRIX!C23+PRIX!D23*$S$6+$T$6*PRIX!E23+PRIX!F23*$U$6+PRIX!G23*$V$6+$W$6*PRIX!H23+PRIX!I23*$X$6) -> 35693.794 | G19: =IF(B19="","",'Historique détail'!U22) -> 36696.807 | H19: =IF(B19="","",(G19-F19)/F19) -> 0.028100479 | I19: =IF(H19="","",(G19-C19)/C19) -> -0.020570216
B20: =IF(ARBITRAGES!E24=0,"",ARBITRAGES!E24) -> 45555 | C20: =IF(F20="","",C19) -> 37467.522 | D20: =IF(F20="","",PRIX!B19) -> 62000 | E20: =IF(F20="","",($F$4/$D$4)*D20) -> 36872.799 | F20: =IF(B20="","",PRIX!B24*$Q$6+$R$6*PRIX!C24+PRIX!D24*$S$6+$T$6*PRIX!E24+PRIX!F24*$U$6+PRIX!G24*$V$6+$W$6*PRIX!H24+PRIX!I24*$X$6) -> 38152.442 | G20: =IF(B20="","",'Historique détail'!U23) -> 37935.52 | H20: =IF(B20="","",(G20-F20)/F20) -> -0.005685668 | I20: =IF(H20="","",(G20-C20)/C20) -> 0.012490773
B21: =IF(ARBITRAGES!E25=0,"",ARBITRAGES!E25) -> 45557 | C21: =IF(F21="","",C20) -> 37467.522 | D21: =IF(F21="","",PRIX!B20) -> 59500 | E21: =IF(F21="","",($F$4/$D$4)*D21) -> 35385.993 | F21: =IF(B21="","",PRIX!B25*$Q$6+$R$6*PRIX!C25+PRIX!D25*$S$6+$T$6*PRIX!E25+PRIX!F25*$U$6+PRIX!G25*$V$6+$W$6*PRIX!H25+PRIX!I25*$X$6) -> 39351.681 | G21: =IF(B21="","",'Historique détail'!U24) -> 40252.678 | H21: =IF(B21="","",(G21-F21)/F21) -> 0.022896017 | I21: =IF(H21="","",(G21-C21)/C21) -> 0.074335216
B22: =IF(ARBITRAGES!E26=0,"",ARBITRAGES!E26) -> 45558 | C22: =IF(F22="","",C21) -> 37467.522 | D22: =IF(F22="","",PRIX!B21) -> 57300 | E22: =IF(F22="","",($F$4/$D$4)*D22) -> 34077.603 | F22: =IF(B22="","",PRIX!B26*$Q$6+$R$6*PRIX!C26+PRIX!D26*$S$6+$T$6*PRIX!E26+PRIX!F26*$U$6+PRIX!G26*$V$6+$W$6*PRIX!H26+PRIX!I26*$X$6) -> 38728.401 | G22: =IF(B22="","",'Historique détail'!U25) -> 41372.68 | H22: =IF(B22="","",(G22-F22)/F22) -> 0.068277526 | I22: =IF(H22="","",(G22-C22)/C22) -> 0.10422783
B23: =IF(ARBITRAGES!E27=0,"",ARBITRAGES!E27) -> 45568 | C23: =IF(F23="","",C22) -> 37467.522 | D23: =IF(F23="","",PRIX!B22) -> 59000 | E23: =IF(F23="","",($F$4/$D$4)*D23) -> 35088.631 | F23: =IF(B23="","",PRIX!B27*$Q$6+$R$6*PRIX!C27+PRIX!D27*$S$6+$T$6*PRIX!E27+PRIX!F27*$U$6+PRIX!G27*$V$6+$W$6*PRIX!H27+PRIX!I27*$X$6) -> 36720.633 | G23: =IF(B23="","",'Historique détail'!U26) -> 40838.915 | H23: =IF(B23="","",(G23-F23)/F23) -> 0.11215171 | I23: =IF(H23="","",(G23-C23)/C23) -> 0.089981761
B24: =IF(ARBITRAGES!E28=0,"",ARBITRAGES!E28) -> 45586 | C24: =IF(F24="","",C23) -> 37467.522 | D24: =IF(F24="","",PRIX!B23) -> 61200 | E24: =IF(F24="","",($F$4/$D$4)*D24) -> 36397.021 | F24: =IF(B24="","",PRIX!B28*$Q$6+$R$6*PRIX!C28+PRIX!D28*$S$6+$T$6*PRIX!E28+PRIX!F28*$U$6+PRIX!G28*$V$6+$W$6*PRIX!H28+PRIX!I28*$X$6) -> 41504.004 | G24: =IF(B24="","",'Historique détail'!U27) -> 38996.089 | H24: =IF(B24="","",(G24-F24)/F24) -> -0.060425844 | I24: =IF(H24="","",(G24-C24)/C24) -> 0.040797133
B25: =IF(ARBITRAGES!E29=0,"",ARBITRAGES!E29) -> 45591 | C25: =IF(F25="","",C24) -> 37467.522 | D25: =IF(F25="","",PRIX!B24) -> 64050 | E25: =IF(F25="","",($F$4/$D$4)*D25) -> 38091.98 | F25: =IF(B25="","",PRIX!B29*$Q$6+$R$6*PRIX!C29+PRIX!D29*$S$6+$T$6*PRIX!E29+PRIX!F29*$U$6+PRIX!G29*$V$6+$W$6*PRIX!H29+PRIX!I29*$X$6) -> 42085.772 | G25: =IF(B25="","",'Historique détail'!U28) -> 43650.544 | H25: =IF(B25="","",(G25-F25)/F25) -> 0.037180538 | I25: =IF(H25="","",(G25-C25)/C25) -> 0.16502352
B26: =IF(ARBITRAGES!E30=0,"",ARBITRAGES!E30) -> 45594 | C26: =IF(F26="","",C25) -> 37467.522 | D26: =IF(F26="","",PRIX!B25) -> 64000 | E26: =IF(F26="","",($F$4/$D$4)*D26) -> 38062.244 | F26: =IF(B26="","",PRIX!B30*$Q$6+$R$6*PRIX!C30+PRIX!D30*$S$6+$T$6*PRIX!E30+PRIX!F30*$U$6+PRIX!G30*$V$6+$W$6*PRIX!H30+PRIX!I30*$X$6) -> 41940.318 | G26: =IF(B26="","",'Historique détail'!U29) -> 44302.285 | H26: =IF(B26="","",(G26-F26)/F26) -> 0.056317336 | I26: =IF(H26="","",(G26-C26)/C26) -> 0.18241833
B27: =IF(ARBITRAGES!E31=0,"",ARBITRAGES!E31) -> 45595 | C27: =IF(F27="","",C26) -> 37467.522 | D27: =IF(F27="","",PRIX!B26) -> 63600 | E27: =IF(F27="","",($F$4/$D$4)*D27) -> 37824.355 | F27: =IF(B27="","",PRIX!B31*$Q$6+$R$6*PRIX!C31+PRIX!D31*$S$6+$T$6*PRIX!E31+PRIX!F31*$U$6+PRIX!G31*$V$6+$W$6*PRIX!H31+PRIX!I31*$X$6) -> 39504.875 | G27: =IF(B27="","",'Historique détail'!U30) -> 44166.08 | H27: =IF(B27="","",(G27-F27)/F27) -> 0.11799065 | I27: =IF(H27="","",(G27-C27)/C27) -> 0.17878307
B28: =IF(ARBITRAGES!E32=0,"",ARBITRAGES!E32) -> 45598 | C28: =IF(F28="","",C27) -> 37467.522 | D28: =IF(F28="","",PRIX!B27) -> 61100 | E28: =IF(F28="","",($F$4/$D$4)*D28) -> 36337.549 | F28: =IF(B28="","",PRIX!B32*$Q$6+$R$6*PRIX!C32+PRIX!D32*$S$6+$T$6*PRIX!E32+PRIX!F32*$U$6+PRIX!G32*$V$6+$W$6*PRIX!H32+PRIX!I32*$X$6) -> 38160.91 | G28: =IF(B28="","",'Historique détail'!U31) -> 41963.675 | H28: =IF(B28="","",(G28-F28)/F28) -> 0.09965079 | I28: =IF(H28="","",(G28-C28)/C28) -> 0.12000136
... B30: =IF(ARBITRAGES!E34=0,"",ARBITRAGES!E34) -> 45602 | C30: =IF(F30="","",C29) -> 37467.522 | D30: =IF(F30="","",PRIX!B29) -> 67000 | E30: =IF(F30="","",($F$4/$D$4)*D30) -> 39846.412 | F30: =IF(B30="","",PRIX!B34*$Q$6+$R$6*PRIX!C34+PRIX!D34*$S$6+$T$6*PRIX!E34+PRIX!F34*$U$6+PRIX!G34*$V$6+$W$6*PRIX!H34+PRIX!I34*$X$6) -> 42788.243 | G30: =IF(B30="","",'Historique détail'!U33) -> 40932.405 | H30: =IF(B30="","",(G30-F30)/F30) -> -0.043372606 | I30: =IF(H30="","",(G30-C30)/C30) -> 0.092476982
B31: =IF(ARBITRAGES!E36=0,"",ARBITRAGES!E36) -> 45576 | C31: =IF(F31="","",C30) -> 37467.522 | D31: =IF(F31="","",PRIX!B30) -> 72500 | E31: =IF(F31="","",($F$4/$D$4)*D31) -> 43117.386 | F31: =IF(B31="","",PRIX!B36*$Q$6+$R$6*PRIX!C36+PRIX!D36*$S$6+$T$6*PRIX!E36+PRIX!F36*$U$6+PRIX!G36*$V$6+$W$6*PRIX!H36+PRIX!I36*$X$6) -> 50465.379 | G31: =IF(B31="","",'Historique détail'!U35) -> 50381.221 | H31: =IF(B31="","",(G31-F31)/F31) -> -0.0016676361 | I31: =IF(H31="","",(G31-C31)/C31) -> 0.34466384
B32: =IF(ARBITRAGES!E37=0,"",ARBITRAGES!E37) -> 45608 | C32: =IF(F32="","",C31) -> 37467.522 | D32: =IF(F32="","",PRIX!B53) -> 92000 | E32: =IF(F32="","",($F$4/$D$4)*D32) -> 54714.476 | F32: =IF(B32="","",PRIX!B37*$Q$6+$R$6*PRIX!C37+PRIX!D37*$S$6+$T$6*PRIX!E37+PRIX!F37*$U$6+PRIX!G37*$V$6+$W$6*PRIX!H37+PRIX!I37*$X$6) -> 51901.244 | G32: =IF(B32="","",'Historique détail'!U36) -> 52869.461 | H32: =IF(B32="","",(G32-F32)/F32) -> 0.018654986 | I32: =IF(H32="","",(G32-C32)/C32) -> 0.4110744
B33: =IF(ARBITRAGES!E38=0,"",ARBITRAGES!E38) -> 45609 | C33: =IF(F33="","",C32) -> 37467.522 | D33: =IF(F33="","",PRIX!B54) -> 94000 | E33: =IF(F33="","",($F$4/$D$4)*D33) -> 55903.921 | F33: =IF(B33="","",PRIX!B38*$Q$6+$R$6*PRIX!C38+PRIX!D38*$S$6+$T$6*PRIX!E38+PRIX!F38*$U$6+PRIX!G38*$V$6+$W$6*PRIX!H38+PRIX!I38*$X$6) -> 48980.286 | G33: =IF(B33="","",'Historique détail'!U37) -> 54208.656 | H33: =IF(B33="","",(G33-F33)/F33) -> 0.10674437 | I33: =IF(H33="","",(G33-C33)/C33) -> 0.44681723
B34: =IF(ARBITRAGES!E41=0,"",ARBITRAGES!E41) -> 45610 | C34: =IF(F34="","",C33) -> 37467.522 | D34: =IF(F34="","",PRIX!B55) -> 88000 | E34: =IF(F34="","",($F$4/$D$4)*D34) -> 52335.586 | F34: =IF(B34="","",PRIX!B41*$Q$6+$R$6*PRIX!C41+PRIX!D41*$S$6+$T$6*PRIX!E41+PRIX!F41*$U$6+PRIX!G41*$V$6+$W$6*PRIX!H41+PRIX!I41*$X$6) -> 51650.258 | G34: =IF(B34="","",'Historique détail'!U40) -> 51415.192 | H34: =IF(B34="","",(G34-F34)/F34) -> -0.0045511073 | I34: =IF(H34="","",(G34-C34)/C34) -> 0.3722603
B35: =IF(ARBITRAGES!E42=0,"",ARBITRAGES!E42) -> 45615 | C35: =IF(F35="","",C34) -> 37467.522 | D35: =IF(F35="","",PRIX!B48) -> 96000 | E35: =IF(F35="","",($F$4/$D$4)*D35) -> 57093.366 | F35: =IF(B35="","",PRIX!B42*$Q$6+$R$6*PRIX!C42+PRIX!D42*$S$6+$T$6*PRIX!E42+PRIX!F42*$U$6+PRIX!G42*$V$6+$W$6*PRIX!H42+PRIX!I42*$X$6) -> 51650.258 | G35: =IF(B35="","",'Historique détail'!U41) -> 53867.707 | H35: =IF(B35="","",(G35-F35)/F35) -> 0.04293199 | I35: =IF(H35="","",(G35-C35)/C35) -> 0.43771737
B36: =IF(ARBITRAGES!E44=0,"",ARBITRAGES!E44) -> 45619 | C36: =IF(F36="","",C35) -> 37467.522 | D36: =IF(F36="","",PRIX!B49) -> 93000 | E36: =IF(F36="","",($F$4/$D$4)*D36) -> 55309.199 | F36: =IF(B36="","",PRIX!B44*$Q$6+$R$6*PRIX!C44+PRIX!D44*$S$6+$T$6*PRIX!E44+PRIX!F44*$U$6+PRIX!G44*$V$6+$W$6*PRIX!H44+PRIX!I44*$X$6) -> 56216.258 | G36: =IF(B36="","",'Historique détail'!U43) -> 58333.004 | H36: =IF(B36="","",(G36-F36)/F36) -> 0.037653627 | I36: =IF(H36="","",(G36-C36)/C36) -> 0.55689519
B37: =IF(ARBITRAGES!E45=0,"",ARBITRAGES!E45) -> 45622 | C37: =IF(F37="","",C36) -> 37467.522 | D37: =IF(F37="","",PRIX!B50) -> 89000 | E37: =IF(F37="","",($F$4/$D$4)*D37) -> 52930.308 | F37: =IF(B37="","",PRIX!B45*$Q$6+$R$6*PRIX!C45+PRIX!D45*$S$6+$T$6*PRIX!E45+PRIX!F45*$U$6+PRIX!G45*$V$6+$W$6*PRIX!H45+PRIX!I45*$X$6) -> 52780.589 | G37: =IF(B37="","",'Historique détail'!U44) -> 58333.004 | H37: =IF(B37="","",(G37-F37)/F37) -> 0.10519805 | I37: =IF(H37="","",(G37-C37)/C37) -> 0.55689519
B38: =IF(ARBITRAGES!E46=0,"",ARBITRAGES!E46) -> 45630 | C38: =IF(F38="","",C37) -> 37467.522 | D38: =IF(F38="","",PRIX!B51) -> 92000 | E38: =IF(F38="","",($F$4/$D$4)*D38) -> 54714.476 | F38: =IF(B38="","",PRIX!B46*$Q$6+$R$6*PRIX!C46+PRIX!D46*$S$6+$T$6*PRIX!E46+PRIX!F46*$U$6+PRIX!G46*$V$6+$W$6*PRIX!H46+PRIX!I46*$X$6) -> 58525.642 | G38: =IF(B38="","",'Historique détail'!U45) -> 55137.786 | H38: =IF(B38="","",(G38-F38)/F38) -> -0.057886684 | I38: =IF(H38="","",(G38-C38)/C38) -> 0.47161552
B39: =IF(ARBITRAGES!E47=0,"",ARBITRAGES!E47) -> 45636 | C39: =IF(F39="","",C38) -> 37467.522 | D39: =IF(F39="","",PRIX!B52) -> 90000 | E39: =IF(F39="","",($F$4/$D$4)*D39) -> 53525.031 | F39: =IF(B39="","",PRIX!B47*$Q$6+$R$6*PRIX!C47+PRIX!D47*$S$6+$T$6*PRIX!E47+PRIX!F47*$U$6+PRIX!G47*$V$6+$W$6*PRIX!H47+PRIX!I47*$X$6) -> 57307.054 | G39: =IF(B39="","",'Historique détail'!U46) -> 61473.762 | H39: =IF(B39="","",(G39-F39)/F39) -> 0.072708467 | I39: =IF(H39="","",(G39-C39)/C39) -> 0.64072134
B40: =IF(ARBITRAGES!E48=0,"",ARBITRAGES!E48) -> 45644 | C40: =IF(F40="","",C39) -> 37467.522 | D40: =IF(F40="","",PRIX!B53) -> 92000 | E40: =IF(F40="","",($F$4/$D$4)*D40) -> 54714.476 | F40: =IF(B40="","",PRIX!B48*$Q$6+$R$6*PRIX!C48+PRIX!D48*$S$6+$T$6*PRIX!E48+PRIX!F48*$U$6+PRIX!G48*$V$6+$W$6*PRIX!H48+PRIX!I48*$X$6) -> 54045.762 | G40: =IF(B40="","",'Historique détail'!U47) -> 60076.062 | H40: =IF(B40="","",(G40-F40)/F40) -> 0.11157768 | I40: =IF(H40="","",(G40-C40)/C40) -> 0.60341703
B41: =IF(ARBITRAGES!E49=0,"",ARBITRAGES!E49) -> 45646 | C41: =IF(F41="","",C40) -> 37467.522 | D41: =IF(F41="","",PRIX!B54) -> 94000 | E41: =IF(F41="","",($F$4/$D$4)*D41) -> 55903.921 | F41: =IF(B41="","",PRIX!B49*$Q$6+$R$6*PRIX!C49+PRIX!D49*$S$6+$T$6*PRIX!E49+PRIX!F49*$U$6+PRIX!G49*$V$6+$W$6*PRIX!H49+PRIX!I49*$X$6) -> 51484.633 | G41: =IF(B41="","",'Historique détail'!U48) -> 56800.476 | H41: =IF(B41="","",(G41-F41)/F41) -> 0.10325108 | I41: =IF(H41="","",(G41-C41)/C41) -> 0.51599236
B42: =IF(ARBITRAGES!E50=0,"",ARBITRAGES!E50) -> 45658 | C42: =IF(F42="","",C41) -> 37467.522 | D42: =IF(F42="","",PRIX!B50) -> 89000 | E42: =IF(F42="","",($F$4/$D$4)*D42) -> 52930.308 | F42: =IF(B42="","",PRIX!B50*$Q$6+$R$6*PRIX!C50+PRIX!D50*$S$6+$T$6*PRIX!E50+PRIX!F50*$U$6+PRIX!G50*$V$6+$W$6*PRIX!H50+PRIX!I50*$X$6) -> 50770.602 | G42: =IF(B42="","",'Historique détail'!U49) -> 54086.409 | H42: =IF(B42="","",(G42-F42)/F42) -> 0.065309584 | I42: =IF(H42="","",(G42-C42)/C42) -> 0.44355449
...

Sheet Historique détail
B1: Historique détaillé | T1: $$$ | V1: %
A2: DATE | B2: $BTC | C2: $ETH | D2: $TON | E2: $SOL | F2: $TAO | G2: $RON | H2: $LINK | I2: $DOGE | J2: $SHIB | K2: $CAKE | L2: $JUP | M2: $AAVE | N2: $CKB | O2: $PENDLE | P2: $BOME | Q2: $PEPE | R2: $WIF | S2: $RAY | T2: USDC | U2: TOTAL | V2: Exposition
A3: =ARBITRAGES!E3 -> 45515 | B3: =IF(A3="","",PRIX!B3*'QUANTITE DETENUES'!B3) -> 6216.5137 | C3: =IF(B3="","",PRIX!C3*'QUANTITE DETENUES'!C3) -> 5059.3988 | D3: =IF(C3="","",PRIX!D3*'QUANTITE DETENUES'!D3) -> 0 | E3: =IF(D3="","",PRIX!E3*'QUANTITE DETENUES'!E3) -> 4858.6938 | F3: =IF(E3="","",PRIX!F3*'QUANTITE DETENUES'!F3) -> 0 | G3: =IF(F3="","",PRIX!G3*'QUANTITE DETENUES'!G3) -> 0 | H3: =IF(G3="","",PRIX!H3*'QUANTITE DETENUES'!H3) -> 0 | I3: =IF(H3="","",PRIX!I3*'QUANTITE DETENUES'!I3) -> 0 | ... R3: =IF(Q3="","",PRIX!R3*'QUANTITE DETENUES'!R3) -> 0 | S3: =IF(R3="","",PRIX!T3*'QUANTITE DETENUES'!S3) -> 0 | T3: =ARBITRAGES!M3 -> 21550 | U3: =IF(A3="","",SUM(B3:T3)) -> 38541.409 | V3: =IF(U3="","",1-T3/U3) -> 0.44086113
A4: =IF(ARBITRAGES!E4="","",ARBITRAGES!E4) -> 45515 | B4: =IF(A4="","",PRIX!B4*'QUANTITE DETENUES'!B4) -> 14363.044 | C4: =IF(B4="","",PRIX!C4*'QUANTITE DETENUES'!C4) -> 5059.3988 | D4: =IF(C4="","",PRIX!D4*'QUANTITE DETENUES'!D4) -> 0 | E4: =IF(D4="","",PRIX!E4*'QUANTITE DETENUES'!E4) -> 4858.6938 | F4: =IF(E4="","",PRIX!F4*'QUANTITE DETENUES'!F4) -> 0 | G4: =IF(F4="","",PRIX!G4*'QUANTITE DETENUES'!G4) -> 0 | H4: =IF(G4="","",PRIX!H4*'QUANTITE DETENUES'!H4) -> 0 | I4: =IF(H4="","",PRIX!I4*'QUANTITE DETENUES'!I4) -> 0 | ... R4: =IF(Q4="","",PRIX!R4*'QUANTITE DETENUES'!R4) -> 0 | S4: =IF(R4="","",PRIX!T4*'QUANTITE DETENUES'!S4) -> 0 | T4: =IF(A4="","",ARBITRAGES!M4) -> 14050 | U4: =IF(A4="","",SUM(B4:T4)) -> 39187.939 | V4: =IF(U4="","",1-T4/U4) -> 0.64147132
A5: =IF(ARBITRAGES!E5="","",ARBITRAGES!E5) -> 45516 | B5: =IF(A5="","",PRIX!B5*'QUANTITE DETENUES'!B5) -> 13633.492 | C5: =IF(B5="","",PRIX!C5*'QUANTITE DETENUES'!C5) -> 8224.174 | D5: =IF(C5="","",PRIX!D5*'QUANTITE DETENUES'!D5) -> 0 | E5: =IF(D5="","",PRIX!E5*'QUANTITE DETENUES'!E5) -> 4645.2628 | F5: =IF(E5="","",PRIX!F5*'QUANTITE DETENUES'!F5) -> 0 | G5: =IF(F5="","",PRIX!G5*'QUANTITE DETENUES'!G5) -> 0 | H5: =IF(G5="","",PRIX!H5*'QUANTITE DETENUES'!H5) -> 0 | I5: =IF(H5="","",PRIX!I5*'QUANTITE DETENUES'!I5) -> 0 | ... R5: =IF(Q5="","",PRIX!R5*'QUANTITE DETENUES'!R5) -> 0 | S5: =IF(R5="","",PRIX!T5*'QUANTITE DETENUES'!S5) -> 0 | T5: =IF(A5="","",ARBITRAGES!M5) -> 11050 | U5: =IF(A5="","",SUM(B5:T5)) -> 38425.058 | V5: =IF(U5="","",1-T5/U5) -> 0.71242724
A6: =IF(ARBITRAGES!E6="","",ARBITRAGES!E6) -> 45517 | B6: =IF(A6="","",PRIX!B6*'QUANTITE DETENUES'!B6) -> 13907.074 | C6: =IF(B6="","",PRIX!C6*'QUANTITE DETENUES'!C6) -> 8322.1902 | D6: =IF(C6="","",PRIX!D6*'QUANTITE DETENUES'!D6) -> 0 | E6: =IF(D6="","",PRIX!E6*'QUANTITE DETENUES'!E6) -> 5787.5965 | F6: =IF(E6="","",PRIX!F6*'QUANTITE DETENUES'!F6) -> 0 | G6: =IF(F6="","",PRIX!G6*'QUANTITE DETENUES'!G6) -> 0 | H6: =IF(G6="","",PRIX!H6*'QUANTITE DETENUES'!H6) -> 0 | I6: =IF(H6="","",PRIX!I6*'QUANTITE DETENUES'!I6) -> 0 | ... R6: =IF(Q6="","",PRIX!R6*'QUANTITE DETENUES'!R6) -> 0 | S6: =IF(R6="","",PRIX!T6*'QUANTITE DETENUES'!S6) -> 0 | T6: =IF(A6="","",ARBITRAGES!M6) -> 9900 | U6: =IF(A6="","",SUM(B6:T6)) -> 38797.452 | V6: =IF(U6="","",1-T6/U6) -> 0.74482861
A7: =IF(ARBITRAGES!E7="","",ARBITRAGES!E7) -> 45518 | B7: =IF(A7="","",PRIX!B7*'QUANTITE DETENUES'!B7) -> 13907.074 | C7: =IF(B7="","",PRIX!C7*'QUANTITE DETENUES'!C7) -> 8322.1902 | D7: =IF(C7="","",PRIX!D7*'QUANTITE DETENUES'!D7) -> 0 | E7: =IF(D7="","",PRIX!E7*'QUANTITE DETENUES'!E7) -> 5787.5965 | F7: =IF(E7="","",PRIX!F7*'QUANTITE DETENUES'!F7) -> 861.9 | G7: =IF(F7="","",PRIX!G7*'QUANTITE DETENUES'!G7) -> 0 | H7: =IF(G7="","",PRIX!H7*'QUANTITE DETENUES'!H7) -> 0 | I7: =IF(H7="","",PRIX!I7*'QUANTITE DETENUES'!I7) -> 0 | ... R7: =IF(Q7="","",PRIX!R7*'QUANTITE DETENUES'!R7) -> 0 | S7: =IF(R7="","",PRIX!T7*'QUANTITE DETENUES'!S7) -> 0 | T7: =IF(A7="","",ARBITRAGES!M7) -> 9060 | U7: =IF(A7="","",SUM(B7:T7)) -> 38816.265 | V7: =IF(U7="","",1-T7/U7) -> 0.76659269
A8: =IF(ARBITRAGES!E8="","",ARBITRAGES!E8) -> 45518 | B8: =IF(A8="","",PRIX!B8*'QUANTITE DETENUES'!B8) -> 13907.074 | C8: =IF(B8="","",PRIX!C8*'QUANTITE DETENUES'!C8) -> 8322.1902 | D8: =IF(C8="","",PRIX!D8*'QUANTITE DETENUES'!D8) -> 0 | E8: =IF(D8="","",PRIX!E8*'QUANTITE DETENUES'!E8) -> 5787.5965 | F8: =IF(E8="","",PRIX!F8*'QUANTITE DETENUES'!F8) -> 861.9 | G8: =IF(F8="","",PRIX!G8*'QUANTITE DETENUES'!G8) -> 330 | H8: =IF(G8="","",PRIX!H8*'QUANTITE DETENUES'!H8) -> 0 | I8: =IF(H8="","",PRIX!I8*'QUANTITE DETENUES'!I8) -> 0 | ... R8: =IF(Q8="","",PRIX!R8*'QUANTITE DETENUES'!R8) -> 0 | S8: =IF(R8="","",PRIX!T8*'QUANTITE DETENUES'!S8) -> 0 | T8: =IF(A8="","",ARBITRAGES!M8) -> 8750 | U8: =IF(A8="","",SUM(B8:T8)) -> 38836.265 | V8: =IF(U8="","",1-T8/U8) -> 0.77469512
A9: =IF(ARBITRAGES!E9="","",ARBITRAGES!E9) -> 45519 | B9: =IF(A9="","",PRIX!B9*'QUANTITE DETENUES'!B9) -> 13223.12 | C9: =IF(B9="","",PRIX!C9*'QUANTITE DETENUES'!C9) -> 8116.9688 | D9: =IF(C9="","",PRIX!D9*'QUANTITE DETENUES'!D9) -> 2758.4877 | E9: =IF(D9="","",PRIX!E9*'QUANTITE DETENUES'!E9) -> 5897.6867 | F9: =IF(E9="","",PRIX!F9*'QUANTITE DETENUES'!F9) -> 819 | G9: =IF(F9="","",PRIX!G9*'QUANTITE DETENUES'!G9) -> 326 | H9: =IF(G9="","",PRIX!H9*'QUANTITE DETENUES'!H9) -> 0 | I9: =IF(H9="","",PRIX!I9*'QUANTITE DETENUES'!I9) -> 0 | ... R9: =IF(Q9="","",PRIX!R9*'QUANTITE DETENUES'!R9) -> 0 | S9: =IF(R9="","",PRIX!T9*'QUANTITE DETENUES'!S9) -> 0 | T9: =IF(A9="","",ARBITRAGES!M9) -> 6000 | U9: =IF(A9="","",SUM(B9:T9)) -> 37999.572 | V9: =IF(U9="","",1-T9/U9) -> 0.84210348
A10: =IF(ARBITRAGES!E10="","",ARBITRAGES!E10) -> 45522 | B10: =IF(A10="","",PRIX!B10*'QUANTITE DETENUES'!B10) -> 15269.714 | C10: =IF(B10="","",PRIX!C10*'QUANTITE DETENUES'!C10) -> 8193.5439 | D10: =IF(C10="","",PRIX!D10*'QUANTITE DETENUES'!D10) -> 2826.3889 | E10: =IF(D10="","",PRIX!E10*'QUANTITE DETENUES'!E10) -> 5756.1422 | F10: =IF(E10="","",PRIX!F10*'QUANTITE DETENUES'!F10) -> 879 | G10: =IF(F10="","",PRIX!G10*'QUANTITE DETENUES'!G10) -> 329.4 | H10: =IF(G10="","",PRIX!H10*'QUANTITE DETENUES'!H10) -> 0 | I10: =IF(H10="","",PRIX!I10*'QUANTITE DETENUES'!I10) -> 0 | ... R10: =IF(Q10="","",PRIX!R10*'QUANTITE DETENUES'!R10) -> 0 | S10: =IF(R10="","",PRIX!T10*'QUANTITE DETENUES'!S10) -> 0 | T10: =IF(A10="","",ARBITRAGES!M10) -> 4500 | U10: =IF(A10="","",SUM(B10:T10)) -> 38621.63 | V10: =IF(U10="","",1-T10/U10) -> 0.88348498
A11: =IF(ARBITRAGES!E11="","",ARBITRAGES!E11) -> 45527 | B11: =IF(A11="","",PRIX!B11*'QUANTITE DETENUES'!B11) -> 16108.151 | C11: =IF(B11="","",PRIX!C11*'QUANTITE DETENUES'!C11) -> 8392.6394 | D11: =IF(C11="","",PRIX!D11*'QUANTITE DETENUES'!D11) -> 2839.1204 | E11: =IF(D11="","",PRIX!E11*'QUANTITE DETENUES'!E11) -> 5851.6847 | F11: =IF(E11="","",PRIX!F11*'QUANTITE DETENUES'!F11) -> 696 | G11: =IF(F11="","",PRIX!G11*'QUANTITE DETENUES'!G11) -> 355.4 | H11: =IF(G11="","",PRIX!H11*'QUANTITE DETENUES'!H11) -> 0 | I11: =IF(H11="","",PRIX!I11*'QUANTITE DETENUES'!I11) -> 0 | ... R11: =IF(Q11="","",PRIX!R11*'QUANTITE DETENUES'!R11) -> 0 | S11: =IF(R11="","",PRIX!T11*'QUANTITE DETENUES'!S11) -> 0 | T11: =IF(A11="","",ARBITRAGES!M11) -> 4845 | U11: =IF(A11="","",SUM(B11:T11)) -> 40071.087 | V11: =IF(U11="","",1-T11/U11) -> 0.87908988
A12: =IF(ARBITRAGES!E12="","",ARBITRAGES!E12) -> 45527 | B12: =IF(A12="","",PRIX!B12*'QUANTITE DETENUES'!B12) -> 16108.151 | C12: =IF(B12="","",PRIX!C12*'QUANTITE DETENUES'!C12) -> 8392.6394 | D12: =IF(C12="","",PRIX!D12*'QUANTITE DETENUES'!D12) -> 2839.1204 | E12: =IF(D12="","",PRIX!E12*'QUANTITE DETENUES'!E12) -> 4411.3944 | F12: =IF(E12="","",PRIX!F12*'QUANTITE DETENUES'!F12) -> 696 | G12: =IF(F12="","",PRIX!G12*'QUANTITE DETENUES'!G12) -> 355.4 | H12: =IF(G12="","",PRIX!H12*'QUANTITE DETENUES'!H12) -> 0 | I12: =IF(H12="","",PRIX!I12*'QUANTITE DETENUES'!I12) -> 0 | ... R12: =IF(Q12="","",PRIX!R12*'QUANTITE DETENUES'!R12) -> 0 | S12: =IF(R12="","",PRIX!T12*'QUANTITE DETENUES'!S12) -> 0 | T12: =IF(A12="","",ARBITRAGES!M12) -> 6345 | U12: =IF(A12="","",SUM(B12:T12)) -> 40130.796 | V12: =IF(U12="","",1-T12/U12) -> 0.841892
A13: =IF(ARBITRAGES!E13="","",ARBITRAGES!E13) -> 45528 | B13: =IF(A13="","",PRIX!B13*'QUANTITE DETENUES'!B13) -> 16362.222 | C13: =IF(B13="","",PRIX!C13*'QUANTITE DETENUES'!C13) -> 8576.4198 | D13: =IF(C13="","",PRIX!D13*'QUANTITE DETENUES'!D13) -> 2871.3735 | E13: =IF(D13="","",PRIX!E13*'QUANTITE DETENUES'!E13) -> 2844.3786 | F13: =IF(E13="","",PRIX!F13*'QUANTITE DETENUES'!F13) -> 686 | G13: =IF(F13="","",PRIX!G13*'QUANTITE DETENUES'!G13) -> 360 | H13: =IF(G13="","",PRIX!H13*'QUANTITE DETENUES'!H13) -> 0 | I13: =IF(H13="","",PRIX!I13*'QUANTITE DETENUES'!I13) -> 0 | ... R13: =IF(Q13="","",PRIX!R13*'QUANTITE DETENUES'!R13) -> 0 | S13: =IF(R13="","",PRIX!T13*'QUANTITE DETENUES'!S13) -> 0 | T13: =IF(A13="","",ARBITRAGES!M13) -> 8178 | U13: =IF(A13="","",SUM(B13:T13)) -> 40893.775 | V13: =IF(U13="","",1-T13/U13) -> 0.80001846
A14: =IF(ARBITRAGES!E14="","",ARBITRAGES!E14) -> 45529 | B14: =IF(A14="","",PRIX!B14*'QUANTITE DETENUES'!B14) -> 16260.594 | C14: =IF(B14="","",PRIX!C14*'QUANTITE DETENUES'!C14) -> 8469.2146 | D14: =IF(C14="","",PRIX!D14*'QUANTITE DETENUES'!D14) -> 2856.1301 | E14: =IF(D14="","",PRIX!E14*'QUANTITE DETENUES'!E14) -> 2844.3786 | F14: =IF(E14="","",PRIX!F14*'QUANTITE DETENUES'!F14) -> 654 | G14: =IF(F14="","",PRIX!G14*'QUANTITE DETENUES'!G14) -> 352 | H14: =IF(G14="","",PRIX!H14*'QUANTITE DETENUES'!H14) -> 0 | I14: =IF(H14="","",PRIX!I14*'QUANTITE DETENUES'!I14) -> 0 | ... R14: =IF(Q14="","",PRIX!R14*'QUANTITE DETENUES'!R14) -> 0 | S14: =IF(R14="","",PRIX!T14*'QUANTITE DETENUES'!S14) -> 0 | T14: =IF(A14="","",ARBITRAGES!M14) -> 7678 | U14: =IF(A14="","",SUM(B14:T14)) -> 40117.46 | V14: =IF(U14="","",1-T14/U14) -> 0.80861201
A15: =IF(ARBITRAGES!E15="","",ARBITRAGES!E15) -> 45530 | B15: =IF(A15="","",PRIX!B15*'QUANTITE DETENUES'!B15) -> 17948.907 | C15: =IF(B15="","",PRIX!C15*'QUANTITE DETENUES'!C15) -> 7963.8184 | D15: =IF(C15="","",PRIX!D15*'QUANTITE DETENUES'!D15) -> 2759.913 | E15: =IF(D15="","",PRIX!E15*'QUANTITE DETENUES'!E15) -> 2772.3691 | F15: =IF(E15="","",PRIX!F15*'QUANTITE DETENUES'!F15) -> 674 | G15: =IF(F15="","",PRIX!G15*'QUANTITE DETENUES'!G15) -> 331.2 | H15: =IF(G15="","",PRIX!H15*'QUANTITE DETENUES'!H15) -> 0 | I15: =IF(H15="","",PRIX!I15*'QUANTITE DETENUES'!I15) -> 0 | ... R15: =IF(Q15="","",PRIX!R15*'QUANTITE DETENUES'!R15) -> 0 | S15: =IF(R15="","",PRIX!T15*'QUANTITE DETENUES'!S15) -> 0 | T15: =IF(A15="","",ARBITRAGES!M15) -> 5478 | U15: =IF(A15="","",SUM(B15:T15)) -> 38900.624 | V15: =IF(U15="","",1-T15/U15) -> 0.85917964
... A26: =IF(ARBITRAGES!E26="","",ARBITRAGES!E26) -> 45558 | B26: =IF(A26="","",PRIX!B26*'QUANTITE DETENUES'!B26) -> 18703.416 | C26: =IF(B26="","",PRIX!C26*'QUANTITE DETENUES'!C26) -> 8116.9688 | D26: =IF(C26="","",PRIX!D26*'QUANTITE DETENUES'!D26) -> 2840.9379 | E26: =IF(D26="","",PRIX!E26*'QUANTITE DETENUES'!E26) -> 2628.3499 | F26: =IF(E26="","",PRIX!F26*'QUANTITE DETENUES'!F26) -> 2663.9985 | G26: =IF(F26="","",PRIX!G26*'QUANTITE DETENUES'!G26) -> 1176 | H26: =IF(G26="","",PRIX!H26*'QUANTITE DETENUES'!H26) -> 1145 | I26: =IF(H26="","",PRIX!I26*'QUANTITE DETENUES'!I26) -> 294.25 | ... R26: =IF(Q26="","",PRIX!R26*'QUANTITE DETENUES'!R26) -> 0 | S26: =IF(R26="","",PRIX!T26*'QUANTITE DETENUES'!S26) -> 0 | T26: =IF(A26="","",ARBITRAGES!M26) -> 2286.14 | U26: =IF(A26="","",SUM(B26:T26)) -> 40838.915 | V26: =IF(U26="","",1-T26/U26) -> 0.94402055
A27: =IF(ARBITRAGES!E27="","",ARBITRAGES!E27) -> 45568 | B27: =IF(A27="","",PRIX!B27*'QUANTITE DETENUES'!B27) -> 17968.219 | C27: =IF(B27="","",PRIX!C27*'QUANTITE DETENUES'!C27) -> 7657.5177 | D27: =IF(C27="","",PRIX!D27*'QUANTITE DETENUES'!D27) -> 2683.9521 | E27: =IF(D27="","",PRIX!E27*'QUANTITE DETENUES'!E27) -> 2484.3307 | F27: =IF(E27="","",PRIX!F27*'QUANTITE DETENUES'!F27) -> 2599.9987 | G27: =IF(F27="","",PRIX!G27*'QUANTITE DETENUES'!G27) -> 1120 | H27: =IF(G27="","",PRIX!H27*'QUANTITE DETENUES'!H27) -> 1060 | I27: =IF(H27="","",PRIX!I27*'QUANTITE DETENUES'!I27) -> 297 | ... R27: =IF(Q27="","",PRIX!R27*'QUANTITE DETENUES'!R27) -> 0 | S27: =IF(R27="","",PRIX!T27*'QUANTITE DETENUES'!S27) -> 0 | T27: =IF(A27="","",ARBITRAGES!M27) -> 2094.14 | U27: =IF(A27="","",SUM(B27:T27)) -> 38996.089 | V27: =IF(U27="","",1-T27/U27) -> 0.94629872 | W27: 1
A28: =IF(ARBITRAGES!E28="","",ARBITRAGES!E28) -> 45586 | B28: =IF(A28="","",PRIX!B28*'QUANTITE DETENUES'!B28) -> 20320.85 | C28: =IF(B28="","",PRIX!C28*'QUANTITE DETENUES'!C28) -> 7698.7158 | D28: =IF(C28="","",PRIX!D28*'QUANTITE DETENUES'!D28) -> 2719.4005 | E28: =IF(D28="","",PRIX!E28*'QUANTITE DETENUES'!E28) -> 3078.4098 | F28: =IF(E28="","",PRIX!F28*'QUANTITE DETENUES'!F28) -> 3073.1984 | G28: =IF(F28="","",PRIX!G28*'QUANTITE DETENUES'!G28) -> 1197 | H28: =IF(G28="","",PRIX!H28*'QUANTITE DETENUES'!H28) -> 1200 | I28: =IF(H28="","",PRIX!I28*'QUANTITE DETENUES'!I28) -> 409.75 | ... R28: =IF(Q28="","",PRIX!R28*'QUANTITE DETENUES'!R28) -> 0 | S28: =IF(R28="","",PRIX!T28*'QUANTITE DETENUES'!S28) -> 0 | T28: =IF(A28="","",ARBITRAGES!M28) -> 2805.52 | U28: =IF(A28="","",SUM(B28:T28)) -> 43650.544 | V28: =IF(U28="","",1-T28/U28) -> 0.93572772
A29: =IF(ARBITRAGES!E29="","",ARBITRAGES!E29) -> 45591 | B29: =IF(A29="","",PRIX!B29*'QUANTITE DETENUES'!B29) -> 19703.284 | C29: =IF(B29="","",PRIX!C29*'QUANTITE DETENUES'!C29) -> 10078.319 | D29: =IF(C29="","",PRIX!D29*'QUANTITE DETENUES'!D29) -> 2694.9806 | E29: =IF(D29="","",PRIX!E29*'QUANTITE DETENUES'!E29) -> 3024.4026 | F29: =IF(E29="","",PRIX!F29*'QUANTITE DETENUES'!F29) -> 2651.9986 | G29: =IF(F29="","",PRIX!G29*'QUANTITE DETENUES'!G29) -> 1050 | H29: =IF(G29="","",PRIX!H29*'QUANTITE DETENUES'!H29) -> 1100 | I29: =IF(H29="","",PRIX!I29*'QUANTITE DETENUES'!I29) -> 368.5 | ... R29: =IF(Q29="","",PRIX!R29*'QUANTITE DETENUES'!R29) -> 0 | S29: =IF(R29="","",PRIX!T29*'QUANTITE DETENUES'!S29) -> 0 | T29: =IF(A29="","",ARBITRAGES!M29) -> 2589.7495 | U29: =IF(A29="","",SUM(B29:T29)) -> 44302.285 | V29: =IF(U29="","",1-T29/U29) -> 0.94154366
A30: =IF(ARBITRAGES!E30="","",ARBITRAGES!E30) -> 45594 | B30: =IF(A30="","",PRIX!B30*'QUANTITE DETENUES'!B30) -> 21320.718 | C30: =IF(B30="","",PRIX!C30*'QUANTITE DETENUES'!C30) -> 7488.7508 | D30: =IF(C30="","",PRIX!D30*'QUANTITE DETENUES'!D30) -> 2777.48 | E30: =IF(D30="","",PRIX!E30*'QUANTITE DETENUES'!E30) -> 3076.7817 | F30: =IF(E30="","",PRIX!F30*'QUANTITE DETENUES'!F30) -> 2885.9985 | G30: =IF(F30="","",PRIX!G30*'QUANTITE DETENUES'!G30) -> 1085 | H30: =IF(G30="","",PRIX!H30*'QUANTITE DETENUES'!H30) -> 1160 | I30: =IF(H30="","",PRIX!I30*'QUANTITE DETENUES'!I30) -> 475.75 | ... R30: =IF(Q30="","",PRIX!R30*'QUANTITE DETENUES'!R30) -> 0 | S30: =IF(R30="","",PRIX!T30*'QUANTITE DETENUES'!S30) -> 0 | T30: =IF(A30="","",ARBITRAGES!M30) -> 2766.2029 | U30: =IF(A30="","",SUM(B30:T30)) -> 44166.08 | V30: =IF(U30="","",1-T30/U30) -> 0.93736816 | W30: 1
A31: =IF(ARBITRAGES!E31="","",ARBITRAGES!E31) -> 45595 | B31: =IF(A31="","",PRIX!B31*'QUANTITE DETENUES'!B31) -> 20585.521 | C31: =IF(B31="","",PRIX!C31*'QUANTITE DETENUES'!C31) -> 6998.8325 | D31: =IF(C31="","",PRIX!D31*'QUANTITE DETENUES'!D31) -> 2749.9802 | E31: =IF(D31="","",PRIX!E31*'QUANTITE DETENUES'!E31) -> 2838.7986 | F31: =IF(E31="","",PRIX!F31*'QUANTITE DETENUES'!F31) -> 2736.9988 | G31: =IF(F31="","",PRIX!G31*'QUANTITE DETENUES'!G31) -> 966 | H31: =IF(G31="","",PRIX!H31*'QUANTITE DETENUES'!H31) -> 1125 | I31: =IF(H31="","",PRIX!I31*'QUANTITE DETENUES'!I31) -> 440 | ... R31: =IF(Q31="","",PRIX!R31*'QUANTITE DETENUES'!R31) -> 0 | S31: =IF(R31="","",PRIX!T31*'QUANTITE DETENUES'!S31) -> 0 | T31: =IF(A31="","",ARBITRAGES!M31) -> 2406.2029 | U31: =IF(A31="","",SUM(B31:T31)) -> 41963.675 | V31: =IF(U31="","",1-T31/U31) -> 0.94265986
A32: =IF(ARBITRAGES!E32="","",ARBITRAGES!E32) -> 45598 | B32: =IF(A32="","",PRIX!B32*'QUANTITE DETENUES'!B32) -> 20144.402 | C32: =IF(B32="","",PRIX!C32*'QUANTITE DETENUES'!C32) -> 6858.8558 | D32: =IF(C32="","",PRIX!D32*'QUANTITE DETENUES'!D32) -> 2529.9818 | E32: =IF(D32="","",PRIX!E32*'QUANTITE DETENUES'!E32) -> 2719.807 | F32: =IF(E32="","",PRIX!F32*'QUANTITE DETENUES'!F32) -> 2498.9989 | G32: =IF(F32="","",PRIX!G32*'QUANTITE DETENUES'!G32) -> 889 | H32: =IF(G32="","",PRIX!H32*'QUANTITE DETENUES'!H32) -> 1060 | I32: =IF(H32="","",PRIX!I32*'QUANTITE DETENUES'!I32) -> 473 | ... R32: =IF(Q32="","",PRIX!R32*'QUANTITE DETENUES'!R32) -> 0 | S32: =IF(R32="","",PRIX!T32*'QUANTITE DETENUES'!S32) -> 0 | T32: =IF(A32="","",ARBITRAGES!M32) -> 1704.9529 | U32: =IF(A32="","",SUM(B32:T32)) -> 40654.557 | V32: =IF(U32="","",1-T32/U32) -> 0.95806244
